<?xml version="1.0" ?>
<robot name="a1_description" xmlns:xacro="http://www.ros.org/wiki/xacro">
  <link name="base">
    <visual>
      <origin rpy="0 0 0" xyz="0 0 0"/>
      <material name="orange"/>
            <geometry>
        <box size="0.10 0.10 0.01"/>
      </geometry>
    </visual>
    <collision>
      <origin rpy="0 0 0" xyz="0 0 0"/>
      <geometry>
        <box size="0.10 0.10 0.01"/>
      </geometry>
    </collision>
    <inertial>
      <mass value="1000"/>
    </inertial>
  </link>
  <joint name="base_stand" type="fixed">
    <origin rpy="0 0 0" xyz="0 0 0"/>
    <parent link="base"/>
    <child link="stand"/>
  </joint>
  <link name="stand">
    <visual>
      <material name="orange"/>
      <origin rpy="0 0 0" xyz="0 0 0.25"/>
      <geometry>
        <box size="0.0245 0.0245 2"/>
      </geometry>
    </visual>
    <collision>
      <origin rpy="0 0 0" xyz="0 0 0.25"/>
      <geometry>
        <box size="0.0245 0.0245 2"/>
      </geometry>
    </collision>
  </link>
  <joint name="stand_imu" type="prismatic">
    <origin rpy="0 0 0" xyz="0 0 0"/>
    <parent link="stand"/>
    <child link="imu"/>
    <axis xyz="0 0 1"/>
    <dynamics damping="0" friction="0"/>
    <limit effort="0.0" lower="0.0" upper="0.5" velocity="52.4"/>
  </joint>
  <link name="imu">
    <inertial>
      <mass value="0.001"/>
      <origin rpy="0 0 0" xyz="0 0 0"/>
      <inertia ixx="0.0001" ixy="0" ixz="0" iyy="0.0001" iyz="0" izz="0.0001"/>
    </inertial>
    <visual>
      <origin rpy="0 0 0" xyz="0 0 0"/>
      <geometry>
        <box size="0.001 0.001 0.001"/>
      </geometry>
      <material name="red"/>
    </visual>
      <origin rpy="0 0 0" xyz="0 0 0"/>
      <geometry>
        <box size=".001 .001 .001"/>
      </geometry>
  </link>
  <joint name="FR_hip_joint" type="revolute">
    <origin rpy="0 0 0" xyz="0 -0.047 0"/>
    <parent link="imu"/>
    <child link="FR_hip"/>
    <axis xyz="1 0 0"/>
    <dynamics damping="0" friction="0"/>
    <limit effort="20" lower="-0.802851455917" upper="0.802851455917" velocity="52.4"/>
  </joint>
  <link name="FR_hip">
    <visual>
      <origin rpy="3.14159265359 0 0" xyz="0 0 0"/>
      <geometry>
        <mesh filename="../meshes/hip.dae" scale="1 1 1"/>
      </geometry>
      <material name="orange"/>
    </visual>
    <collision>
      <origin rpy="1.57079632679 0 0" xyz="0 0 0"/>
      <geometry>
        <cylinder length="0.04" radius="0.046"/>
      </geometry>
    </collision>
    <inertial>
      <origin rpy="0 0 0" xyz="-0.003311 -0.000635 3.1e-05"/>
      <mass value="0.696"/>
      <inertia ixx="0.000469246" ixy="9.409e-06" ixz="-3.42e-07" iyy="0.00080749" iyz="4.66e-07" izz="0.000552929"/>
    </inertial>
  </link>
  <joint name="FR_hip_fixed" type="fixed">
    <origin rpy="0 0 0" xyz="0 -0.081 0"/>
    <parent link="FR_hip"/>
    <child link="FR_thigh_shoulder"/>
  </joint>
  <link name="FR_thigh_shoulder">
    <collision>
      <origin rpy="1.57079632679 0 0" xyz="0 0 0"/>
      <geometry>
        <cylinder length="0.032" radius="0.041"/>
      </geometry>
    </collision>
  </link>
  <joint name="FR_thigh_joint" type="revolute">
    <origin rpy="0 0 0" xyz="0 -0.08505 0"/>
    <parent link="FR_hip"/>
    <child link="FR_thigh"/>
    <axis xyz="0 1 0"/>
    <dynamics damping="0" friction="0"/>
    <limit effort="55" lower="-1.0471975512" upper="4.18879020479" velocity="28.6"/>
  </joint>
  <link name="FR_thigh">
    <visual>
      <origin rpy="0 0 0" xyz="0 0 0"/>
      <geometry>
        <mesh filename="../meshes/thigh_mirror.dae" scale="1 1 1"/>
      </geometry>
      <material name="orange"/>
    </visual>
    <collision>
      <origin rpy="0 1.57079632679 0" xyz="0 0 -0.1"/>
      <geometry>
        <box size="0.2 0.0245 0.034"/>
      </geometry>
    </collision>
    <inertial>
      <origin rpy="0 0 0" xyz="-0.003237 0.022327 -0.027326"/>
      <mass value="1.013"/>
      <inertia ixx="0.005529065" ixy="-4.825e-06" ixz="0.000343869" iyy="0.005139339" iyz="-2.2448e-05" izz="0.001367788"/>
    </inertial>
  </link>
  <joint name="FR_calf_joint" type="revolute">
    <origin rpy="0 0 0" xyz="0 0 -0.2"/>
    <parent link="FR_thigh"/>
    <child link="FR_calf"/>
    <axis xyz="0 1 0"/>
    <dynamics damping="0" friction="0"/>
    <limit effort="55" lower="-2.69653369433" upper="-0.916297857297" velocity="28.6"/>
  </joint>
  <link name="FR_calf">
    <visual>
      <origin rpy="0 0 0" xyz="0 0 0"/>
      <geometry>
        <mesh filename="../meshes/calf.dae" scale="1 1 1"/>
      </geometry>
      <material name="orange"/>
    </visual>
    <collision>
      <origin rpy="0 1.57079632679 0" xyz="0 0 -0.1"/>
      <geometry>
        <box size="0.2 0.016 0.016"/>
      </geometry>
    </collision>
    <inertial>
      <origin rpy="0 0 0" xyz="0.006435 0.0 -0.107388"/>
      <mass value="0.166"/>
      <inertia ixx="0.002997972" ixy="0.0" ixz="-0.000141163" iyy="0.003014022" iyz="0.0" izz="3.2426e-05"/>
    </inertial>
  </link>
  <joint name="FR_foot_fixed" type="fixed" dont_collapse="true">
    <origin rpy="0 0 0" xyz="0 0 -0.2"/>
    <parent link="FR_calf"/>
    <child link="FR_foot"/>
  </joint>
  <link name="FR_foot">
    <visual>
      <origin rpy="0 0 0" xyz="0 0 0"/>
      <geometry>
        <sphere radius="0.01"/>
      </geometry>
      <material name="orange"/>
    </visual>
    <collision>
      <origin rpy="0 0 0" xyz="0 0 0"/>
      <geometry>
        <sphere radius="0.02"/>
      </geometry>
    </collision>
    <inertial>
      <mass value="0.06"/>
      <inertia ixx="9.6e-06" ixy="0.0" ixz="0.0" iyy="9.6e-06" iyz="0.0" izz="9.6e-06"/>
    </inertial>
  </link>
</robot>